Workbook

Sheet Blad1
B7: Pin | C7: Tag | D7: Signal Type | E7: Signal Type Description | F7: Application Name 1 | G7: Application Name 2
B8: ~ 0/RX0 | E8: =IF($D8="","",VLOOKUP(D8,Blad2!$A$4:$B$7,2))
B9: ~ 1/TX0 | E9: =IF($D9="","",VLOOKUP(D9,Blad2!$A$4:$B$7,2))
B10: ~ 2 | C10: stpTurn | D10: DO | E10: =IF($D10="","",VLOOKUP(D10,Blad2!$A$4:$B$7,2)) -> Digital Out | F10: Turn Coordinator | G10: Stepper Turn Indicator
B11: ~ 3 | C11: stpTurn | D11: DO | E11: =IF($D11="","",VLOOKUP(D11,Blad2!$A$4:$B$7,2)) -> Digital Out | F11: Turn Coordinator | G11: Stepper Turn Indicator
B12: ~ 4 | C12: stpTurn | D12: DO | E12: =IF($D12="","",VLOOKUP(D12,Blad2!$A$4:$B$7,2)) -> Digital Out | F12: Turn Coordinator | G12: Stepper Turn Indicator
B13: ~ 5 | C13: stpTurn | D13: DO | E13: =IF($D13="","",VLOOKUP(D13,Blad2!$A$4:$B$7,2)) -> Digital Out | F13: Turn Coordinator | G13: Stepper Turn Indicator
B14: ~ 6 | E14: =IF($D14="","",VLOOKUP(D14,Blad2!$A$4:$B$7,2))
B15: ~ 7 | E15: =IF($D15="","",VLOOKUP(D15,Blad2!$A$4:$B$7,2))
B16: ~ 8 | C16: panel_LT | D16: PWM | E16: =IF($D16="","",VLOOKUP(D16,Blad2!$A$4:$B$7,2)) -> PWM Out | F16: Panel Lighting | G16: Panel lighting strenght
B17: ~ 9 | E17: =IF($D17="","",VLOOKUP(D17,Blad2!$A$4:$B$7,2))
B18: ~ 10 | E18: =IF($D18="","",VLOOKUP(D18,Blad2!$A$4:$B$7,2))
B19: ~ 11 | E19: =IF($D19="","",VLOOKUP(D19,Blad2!$A$4:$B$7,2))
B20: ~ 12 | E20: =IF($D20="","",VLOOKUP(D20,Blad2!$A$4:$B$7,2))
B21: ~ 13 | E21: =IF($D21="","",VLOOKUP(D21,Blad2!$A$4:$B$7,2))
B22: 14/TX3 | E22: =IF($D22="","",VLOOKUP(D22,Blad2!$A$4:$B$7,2))
B23: 15/RX3 | E23: =IF($D23="","",VLOOKUP(D23,Blad2!$A$4:$B$7,2))
B24: 16/TX2 | E24: =IF($D24="","",VLOOKUP(D24,Blad2!$A$4:$B$7,2))
B25: 17/RX2 | E25: =IF($D25="","",VLOOKUP(D25,Blad2!$A$4:$B$7,2))
B26: 18/TX1 | C26: stpBall | D26: DO | E26: =IF($D26="","",VLOOKUP(D26,Blad2!$A$4:$B$7,2)) -> Digital Out | F26: Turn Coordinator | G26: Stepper Ball Indicator
B27: 19/RX1 | C27: stpBall | D27: DO | E27: =IF($D27="","",VLOOKUP(D27,Blad2!$A$4:$B$7,2)) -> Digital Out | F27: Turn Coordinator | G27: Stepper Ball Indicator
B28: 20/SDA | C28: stpBall | D28: DO | E28: =IF($D28="","",VLOOKUP(D28,Blad2!$A$4:$B$7,2)) -> Digital Out | F28: Turn Coordinator | G28: Stepper Ball Indicator
B29: 21/SCL | C29: stpBall | D29: DO | E29: =IF($D29="","",VLOOKUP(D29,Blad2!$A$4:$B$7,2)) -> Digital Out | F29: Turn Coordinator | G29: Stepper Ball Indicator
B30: 22 | C30: stpSpeed | D30: DO | E30: =IF($D30="","",VLOOKUP(D30,Blad2!$A$4:$B$7,2)) -> Digital Out | F30: Airspeed Indicator | G30: Stepper Speed Indicator
B31: 23 | C31: stpSpeed | D31: DO | E31: =IF($D31="","",VLOOKUP(D31,Blad2!$A$4:$B$7,2)) -> Digital Out | F31: Airspeed Indicator | G31: Stepper Speed Indicator
B32: 24 | C32: stpSpeed | D32: DO | E32: =IF($D32="","",VLOOKUP(D32,Blad2!$A$4:$B$7,2)) -> Digital Out | F32: Airspeed Indicator | G32: Stepper Speed Indicator
B33: 25 | C33: stpSpeed | D33: DO | E33: =IF($D33="","",VLOOKUP(D33,Blad2!$A$4:$B$7,2)) -> Digital Out | F33: Airspeed Indicator | G33: Stepper Speed Indicator
B34: 26 | C34: stpRoll | D34: DO | E34: =IF($D34="","",VLOOKUP(D34,Blad2!$A$4:$B$7,2)) -> Digital Out | F34: Attitude Indicator | G34: Stepper Roll Angle
B35: 27 | C35: stpRoll | D35: DO | E35: =IF($D35="","",VLOOKUP(D35,Blad2!$A$4:$B$7,2)) -> Digital Out | F35: Attitude Indicator | G35: Stepper Roll Angle
B36: 28 | C36: stpRoll | D36: DO | E36: =IF($D36="","",VLOOKUP(D36,Blad2!$A$4:$B$7,2)) -> Digital Out | F36: Attitude Indicator | G36: Stepper Roll Angle
B37: 29 | C37: stpRoll | D37: DO | E37: =IF($D37="","",VLOOKUP(D37,Blad2!$A$4:$B$7,2)) -> Digital Out | F37: Attitude Indicator | G37: Stepper Roll Angle
B38: 30 | C38: stpPitch | D38: DO | E38: =IF($D38="","",VLOOKUP(D38,Blad2!$A$4:$B$7,2)) -> Digital Out | F38: Attitude Indicator | G38: Stepper Pitch Angle
B39: 31 | C39: stpPitch | D39: DO | E39: =IF($D39="","",VLOOKUP(D39,Blad2!$A$4:$B$7,2)) -> Digital Out | F39: Attitude Indicator | G39: Stepper Pitch Angle
B40: 32 | C40: stpPitch | D40: DO | E40: =IF($D40="","",VLOOKUP(D40,Blad2!$A$4:$B$7,2)) -> Digital Out | F40: Attitude Indicator | G40: Stepper Pitch Angle
B41: 33 | C41: stpPitch | D41: DO | E41: =IF($D41="","",VLOOKUP(D41,Blad2!$A$4:$B$7,2)) -> Digital Out | F41: Attitude Indicator | G41: Stepper Pitch Angle
... B43: 35 | C43: stpAltitude | D43: DO | E43: =IF($D43="","",VLOOKUP(D43,Blad2!$A$4:$B$7,2)) -> Digital Out | F43: Altimeter | G43: Stepper Altitude
B44: 36 | C44: stpAltitude | D44: DO | E44: =IF($D44="","",VLOOKUP(D44,Blad2!$A$4:$B$7,2)) -> Digital Out | F44: Altimeter | G44: Stepper Altitude | P44: +
B45: 37 | C45: stpAltitude | D45: DO | E45: =IF($D45="","",VLOOKUP(D45,Blad2!$A$4:$B$7,2)) -> Digital Out | F45: Altimeter | G45: Stepper Altitude
B46: 38 | C46: stpVario | D46: DO | E46: =IF($D46="","",VLOOKUP(D46,Blad2!$A$4:$B$7,2)) -> Digital Out | F46: Variometer | G46: Stepper Variometer
B47: 39 | C47: stpVario | D47: DO | E47: =IF($D47="","",VLOOKUP(D47,Blad2!$A$4:$B$7,2)) -> Digital Out | F47: Variometer | G47: Stepper Variometer
...

Sheet Blad2
A4: AI | B4: Analog In
A5: DI | B5: Digital In
A6: DO | B6: Digital Out
A7: PWM | B7: PWM Out
